Workbook

Sheet financial data sp500 companies
A1: S. NO. | B1: date | C1: firm | D1: Ticker | E1: Research Development | F1: Income Before Tax | G1: Net Income | H1: Selling General Administrative | I1: Gross Profit | J1: Ebit | K1: Operating Income | L1: Interest Expense | M1: Income Tax Expense | N1: Total Revenue | O1: Total Operating Expenses | P1: Cost Of Revenue | Q1: Total Other Income Expense Net | R1: Net Income From Continuing Ops | S1: Net Income Applicable To Common Shares
A2: 0 | B2: 44469 | C2: 3M | D2: MMM | E2: 482000000 | F2: 1761000000 | G2: 1434000000 | H2: 1739000000 | I2: 4089000000 | J2: 1868000000 | K2: 1868000000 | L2: -117000000 | M2: 324000000 | N2: 8942000000 | O2: 7074000000 | P2: 4853000000 | Q2: -107000000 | R2: 1437000000 | S2: 1434000000
A3: 1 | B3: 44377 | C3: 3M | D3: MMM | E3: 514000000 | F3: 1940000000 | G3: 1524000000 | H3: 1666000000 | I3: 4231000000 | J3: 2051000000 | K3: 2051000000 | L3: -121000000 | M3: 415000000 | N3: 8950000000 | O3: 6899000000 | P3: 4719000000 | Q3: -111000000 | R3: 1525000000 | S3: 1524000000
A4: 2 | B4: 44286 | C4: 3M | D4: MMM | E4: 520000000 | F4: 1946000000 | G4: 1624000000 | H4: 1720000000 | I4: 4327000000 | J4: 2087000000 | K4: 2087000000 | L4: -132000000 | M4: 319000000 | N4: 8851000000 | O4: 6764000000 | P4: 4524000000 | Q4: -141000000 | R4: 1627000000 | S4: 1624000000
A5: 3 | B5: 44196 | C5: 3M | D5: MMM | E5: 449000000 | F5: 1706000000 | G5: 1389000000 | H5: 1814000000 | I5: 4246000000 | J5: 1983000000 | K5: 1983000000 | L5: -141000000 | M5: 316000000 | N5: 8583000000 | O5: 6600000000 | P5: 4337000000 | Q5: -277000000 | R5: 1390000000 | S5: 1389000000
A6: 4 | B6: 44469 | C6: 3M | D6: MMM | E6: 482000000 | F6: 1761000000 | G6: 1434000000 | H6: 1739000000 | I6: 4089000000 | J6: 1868000000 | K6: 1868000000 | L6: -117000000 | M6: 324000000 | N6: 8942000000 | O6: 7074000000 | P6: 4853000000 | Q6: -107000000 | R6: 1437000000 | S6: 1434000000
A7: 5 | B7: 44377 | C7: 3M | D7: MMM | E7: 514000000 | F7: 1940000000 | G7: 1524000000 | H7: 1666000000 | I7: 4231000000 | J7: 2051000000 | K7: 2051000000 | L7: -121000000 | M7: 415000000 | N7: 8950000000 | O7: 6899000000 | P7: 4719000000 | Q7: -111000000 | R7: 1525000000 | S7: 1524000000
A8: 6 | B8: 44286 | C8: 3M | D8: MMM | E8: 520000000 | F8: 1946000000 | G8: 1624000000 | H8: 1720000000 | I8: 4327000000 | J8: 2087000000 | K8: 2087000000 | L8: -132000000 | M8: 319000000 | N8: 8851000000 | O8: 6764000000 | P8: 4524000000 | Q8: -141000000 | R8: 1627000000 | S8: 1624000000
A9: 7 | B9: 44196 | C9: 3M | D9: MMM | E9: 449000000 | F9: 1706000000 | G9: 1389000000 | H9: 1814000000 | I9: 4246000000 | J9: 1983000000 | K9: 1983000000 | L9: -141000000 | M9: 316000000 | N9: 8583000000 | O9: 6600000000 | P9: 4337000000 | Q9: -277000000 | R9: 1390000000 | S9: 1389000000
A10: 8 | B10: 44469 | C10: A. O. Smith | D10: AOS | F10: 166400000 | G10: 131600000 | H10: 174300000 | I10: 340300000 | J10: 166000000 | K10: 166000000 | L10: -1000000 | M10: 34800000 | N10: 914600000 | O10: 748600000 | P10: 574300000 | Q10: 400000 | R10: 131600000 | S10: 131600000
A11: 9 | B11: 44377 | C11: A. O. Smith | D11: AOS | F11: 151300000 | G11: 118200000 | H11: 169800000 | I11: 321400000 | J11: 151600000 | K11: 151600000 | L11: -900000 | M11: 33100000 | N11: 859800000 | O11: 708200000 | P11: 538400000 | Q11: -300000 | R11: 118200000 | S11: 118200000
A12: 10 | B12: 44286 | C12: A. O. Smith | D12: AOS | F12: 126100000 | G12: 97700000 | H12: 166500000 | I12: 288600000 | J12: 122100000 | K12: 122100000 | L12: -1000000 | M12: 28400000 | N12: 769000000 | O12: 646900000 | P12: 480400000 | Q12: 4000000 | R12: 97700000 | S12: 97700000
A13: 11 | B13: 44196 | C13: A. O. Smith | D13: AOS | F13: 151900000 | G13: 120000000 | H13: 184700000 | I13: 324100000 | J13: 139400000 | K13: 139400000 | L13: -1000000 | M13: 31900000 | N13: 834500000 | O13: 695100000 | P13: 510400000 | Q13: 12500000 | R13: 120000000 | S13: 120000000
A14: 12 | B14: 44469 | C14: Abbott Laboratories | D14: ABT | E14: 672000000 | F14: 2493000000 | G14: 2100000000 | H14: 2699000000 | I14: 6505000000 | J14: 2614000000 | K14: 2614000000 | L14: -133000000 | M14: 393000000 | N14: 10928000000 | O14: 8314000000 | P14: 4423000000 | Q14: -121000000 | R14: 2100000000 | S14: 2092000000
A15: 13 | B15: 44377 | C15: Abbott Laboratories | D15: ABT | E15: 654000000 | F15: 1348000000 | G15: 1189000000 | H15: 2658000000 | I15: 5786000000 | J15: 1970000000 | K15: 1970000000 | L15: -134000000 | M15: 159000000 | N15: 10223000000 | O15: 8253000000 | P15: 4437000000 | Q15: -622000000 | R15: 1189000000 | S15: 1184000000
A16: 14 | B16: 44286 | C16: Abbott Laboratories | D16: ABT | E16: 654000000 | F16: 2043000000 | G16: 1793000000 | H16: 2716000000 | I16: 6056000000 | J16: 2177000000 | K16: 2177000000 | L16: -135000000 | M16: 250000000 | N16: 10456000000 | O16: 8279000000 | P16: 4400000000 | Q16: -134000000 | R16: 1793000000 | S16: 1785000000
A17: 15 | B17: 44196 | C17: Abbott Laboratories | D17: ABT | E17: 643000000 | F17: 2388000000 | G17: 2162000000 | H17: 2525000000 | I17: 6207000000 | J17: 2531000000 | K17: 2531000000 | L17: -136000000 | M17: 230000000 | N17: 10701000000 | O17: 8170000000 | P17: 4494000000 | Q17: -143000000 | R17: 2158000000 | S17: 2151000000
A18: 16 | B18: 44469 | C18: AbbVie | D18: ABBV | E18: 1655000000 | F18: 3688000000 | G18: 3179000000 | H18: 2946000000 | I18: 9998000000 | J18: 4897000000 | K18: 4897000000 | L18: -596000000 | M18: 508000000 | N18: 14342000000 | O18: 9445000000 | P18: 4344000000 | Q18: -1209000000 | R18: 3180000000 | S18: 3158000000
A19: 17 | B19: 44377 | C19: AbbVie | D19: ABBV | E19: 1784000000 | F19: 1163000000 | G19: 766000000 | H19: 3049000000 | I19: 9461000000 | J19: 4696000000 | K19: 4696000000 | L19: -615000000 | M19: 394000000 | N19: 13959000000 | O19: 9263000000 | P19: 4498000000 | Q19: -3533000000 | R19: 769000000 | S19: 751000000
A20: 18 | B20: 44286 | C20: AbbVie | D20: ABBV | E20: 1731000000 | F20: 3867000000 | G20: 3553000000 | H20: 2741000000 | I20: 8818000000 | J20: 4346000000 | K20: 4346000000 | L20: -632000000 | M20: 312000000 | N20: 13010000000 | O20: 8664000000 | P20: 4192000000 | Q20: -479000000 | R20: 3555000000 | S20: 3536000000
A21: 19 | B21: 44196 | C21: AbbVie | D21: ABBV | E21: 1821000000 | F21: -1507000000 | G21: 36000000 | H21: 3099000000 | I21: 10448000000 | J21: 5528000000 | K21: 5528000000 | L21: -629000000 | M21: -1545000000 | N21: 13858000000 | O21: 8330000000 | P21: 3410000000 | Q21: -7035000000 | R21: 38000000 | S21: 20000000
A22: 20 | B22: 44469 | C22: Abiomed | D22: ABMD | E22: 41041000 | F22: 67271000 | G22: 56953000 | H22: 102779000 | I22: 204256000 | J22: 60436000 | K22: 60436000 | M22: 10318000 | N22: 248142000 | O22: 187706000 | P22: 43886000 | Q22: 6835000 | R22: 56953000 | S22: 56953000
A23: 21 | B23: 44377 | C23: Abiomed | D23: ABMD | E23: 36837000 | F23: -9350000 | G23: -26525000 | H23: 103484000 | I23: 207397000 | J23: 67076000 | K23: 67076000 | M23: 17175000 | N23: 252585000 | O23: 185509000 | P23: 45188000 | Q23: -76426000 | R23: -26525000 | S23: -26525000
A24: 22 | B24: 44286 | C24: Abiomed | D24: ABMD | E24: 32599000 | F24: 73494000 | G24: 56856000 | H24: 100374000 | I24: 195167000 | J24: 62194000 | K24: 62194000 | M24: 16638000 | N24: 241245000 | O24: 179051000 | P24: 46078000 | Q24: 11300000 | R24: 56856000 | S24: 56856000
A25: 23 | B25: 44196 | C25: Abiomed | D25: ABMD | E25: 32105000 | F25: 80735000 | G25: 61868000 | H25: 86198000 | I25: 190553000 | J25: 72250000 | K25: 72250000 | M25: 18867000 | N25: 231663000 | O25: 159413000 | P25: 41110000 | Q25: 8485000 | R25: 61868000 | S25: 61868000
A26: 24 | B26: 44439 | C26: Accenture | D26: ACN | F26: 1917805000 | G26: 1416248000 | H26: 2507527000 | I26: 4466216000 | J26: 1958689000 | K26: 1958689000 | L26: -12977000 | M26: 480382000 | N26: 13419284000 | O26: 11460595000 | P26: 8953068000 | Q26: -40884000 | R26: 1437423000 | S26: 1416248000
A27: 25 | B27: 44347 | C27: Accenture | D27: ACN | F27: 2094001000 | G27: 1549426000 | H27: 2285728000 | I27: 4404384000 | J27: 2118656000 | K27: 2118656000 | L27: -28739000 | M27: 524429000 | N27: 13263795000 | O27: 11145139000 | P27: 8859411000 | Q27: -24655000 | R27: 1569572000 | S27: 1549426000
A28: 26 | B28: 44255 | C28: Accenture | D28: ACN | F28: 1762443000 | G28: 1440859000 | H28: 1941717000 | I28: 3595232000 | J28: 1653515000 | K28: 1653515000 | L28: -8922000 | M28: 300950000 | N28: 12088125000 | O28: 10434610000 | P28: 8492893000 | Q28: 108928000 | R28: 1461493000 | S28: 1440859000
A29: 27 | B29: 44165 | C29: Accenture | D29: ACN | F29: 1986867000 | G29: 1500276000 | H29: 2007627000 | I29: 3898296000 | J29: 1890669000 | K29: 1890669000 | L29: -8854000 | M29: 464810000 | N29: 11762185000 | O29: 9871516000 | P29: 7863889000 | Q29: 96198000 | R29: 1522057000 | S29: 1500276000
A30: 28 | B30: 44469 | C30: Activision Blizzard | D30: ATVI | E30: 329000000 | F30: 759000000 | G30: 639000000 | H30: 387000000 | I30: 1543000000 | J30: 827000000 | K30: 827000000 | L30: -27000000 | M30: 120000000 | N30: 2070000000 | O30: 1243000000 | P30: 527000000 | Q30: -68000000 | R30: 639000000 | S30: 639000000
A31: 29 | B31: 44377 | C31: Activision Blizzard | D31: ATVI | E31: 335000000 | F31: 1002000000 | G31: 876000000 | H31: 434000000 | I31: 1741000000 | J31: 972000000 | K31: 972000000 | L31: -27000000 | M31: 126000000 | N31: 2296000000 | O31: 1324000000 | P31: 555000000 | Q31: 30000000 | R31: 876000000 | S31: 876000000
A32: 30 | B32: 44286 | C32: Activision Blizzard | D32: ATVI | E32: 353000000 | F32: 765000000 | G32: 619000000 | H32: 519000000 | I32: 1697000000 | J32: 825000000 | K32: 825000000 | L32: -28000000 | M32: 146000000 | N32: 2275000000 | O32: 1450000000 | P32: 578000000 | Q32: -60000000 | R32: 619000000 | S32: 619000000
A33: 31 | B33: 44196 | C33: Activision Blizzard | D33: ATVI | E33: 348000000 | F33: 563000000 | G33: 509000000 | H33: 597000000 | I33: 1595000000 | J33: 650000000 | K33: 650000000 | L33: -27000000 | M33: 54000000 | N33: 2412000000 | O33: 1762000000 | P33: 817000000 | Q33: -87000000 | R33: 509000000 | S33: 509000000
A34: 32 | B34: 44469 | C34: ADM | D34: ADM | F34: 653000000 | G34: 526000000 | H34: 716000000 | I34: 1326000000 | J34: 607000000 | K34: 607000000 | L34: -61000000 | M34: 120000000 | N34: 20340000000 | O34: 19733000000 | P34: 19014000000 | Q34: 46000000 | R34: 533000000 | S34: 526000000
A35: 33 | B35: 44377 | C35: ADM | D35: ADM | F35: 825000000 | G35: 712000000 | H35: 815000000 | I35: 1463000000 | J35: 642000000 | K35: 642000000 | L35: -40000000 | M35: 113000000 | N35: 22926000000 | O35: 22284000000 | P35: 21463000000 | Q35: 183000000 | R35: 712000000 | S35: 712000000
A36: 34 | B36: 44286 | C36: ADM | D36: ADM | F36: 824000000 | G36: 689000000 | H36: 697000000 | I36: 1548000000 | J36: 843000000 | K36: 843000000 | L36: -87000000 | M36: 131000000 | N36: 18893000000 | O36: 18050000000 | P36: 17345000000 | Q36: -19000000 | R36: 693000000 | S36: 689000000
A37: 35 | B37: 44196 | C37: ADM | D37: ADM | F37: 756000000 | G37: 687000000 | H37: 720000000 | I37: 1352000000 | J37: 615000000 | K37: 615000000 | L37: -69000000 | M37: 63000000 | N37: 17978000000 | O37: 17363000000 | P37: 16626000000 | Q37: 141000000 | R37: 693000000 | S37: 687000000
A38: 36 | B38: 44442 | C38: Adobe | D38: ADBE | E38: 651000000 | F38: 1418000000 | G38: 1212000000 | H38: 1333000000 | I38: 3468000000 | J38: 1441000000 | K38: 1441000000 | L38: -27000000 | M38: 206000000 | N38: 3935000000 | O38: 2494000000 | P38: 467000000 | Q38: -23000000 | R38: 1212000000 | S38: 1212000000
A39: 37 | B39: 44351 | C39: Adobe | D39: ADBE | E39: 612000000 | F39: 1386000000 | G39: 1116000000 | H39: 1329000000 | I39: 3391000000 | J39: 1406000000 | K39: 1406000000 | L39: -28000000 | M39: 270000000 | N39: 3835000000 | O39: 2429000000 | P39: 444000000 | Q39: -20000000 | R39: 1116000000 | S39: 1116000000
A40: 38 | B40: 44260 | C40: Adobe | D40: ADBE | E40: 620000000 | F40: 1433000000 | G40: 1261000000 | H40: 1339000000 | I40: 3458000000 | J40: 1454000000 | K40: 1454000000 | L40: -30000000 | M40: 172000000 | N40: 3905000000 | O40: 2451000000 | P40: 447000000 | Q40: -21000000 | R40: 1261000000 | S40: 1261000000
...

Sheet Raw_Data
A1: S. NO. | B1: date | C1: firm | D1: Ticker | E1: Research Development | F1: Income Before Tax | G1: Net Income | H1: Selling General Administrative | I1: Gross Profit | J1: Ebit | K1: Operating Income | L1: Interest Expense | M1: Income Tax Expense | N1: Total Revenue | O1: Total Operating Expenses | P1: Cost Of Revenue | Q1: Total Other Income Expense Net | R1: Net Income From Continuing Ops | S1: Net Income Applicable To Common Shares
A2: 0 | B2: 44469 | C2: 3M | D2: MMM | E2: 482000000 | F2: 1761000000 | G2: 1434000000 | H2: 1739000000 | I2: 4089000000 | J2: 1868000000 | K2: 1868000000 | L2: -117000000 | M2: 324000000 | N2: 8942000000 | O2: 7074000000 | P2: 4853000000 | Q2: -107000000 | R2: 1437000000 | S2: 1434000000
A3: 1 | B3: 44377 | C3: 3M | D3: MMM | E3: 514000000 | F3: 1940000000 | G3: 1524000000 | H3: 1666000000 | I3: 4231000000 | J3: 2051000000 | K3: 2051000000 | L3: -121000000 | M3: 415000000 | N3: 8950000000 | O3: 6899000000 | P3: 4719000000 | Q3: -111000000 | R3: 1525000000 | S3: 1524000000 | W3: =Raw_Data!C2&"|"&Raw_Data!D2&"|"&TEXT(Raw_Data!B2,"yyyy-mm-dd") -> 3M|MMM|2021-09-30
A4: 2 | B4: 44286 | C4: 3M | D4: MMM | E4: 520000000 | F4: 1946000000 | G4: 1624000000 | H4: 1720000000 | I4: 4327000000 | J4: 2087000000 | K4: 2087000000 | L4: -132000000 | M4: 319000000 | N4: 8851000000 | O4: 6764000000 | P4: 4524000000 | Q4: -141000000 | R4: 1627000000 | S4: 1624000000 | W4: =Raw_Data!C3&"|"&Raw_Data!D3&"|"&TEXT(Raw_Data!B3,"yyyy-mm-dd") -> 3M|MMM|2021-06-30
A5: 3 | B5: 44196 | C5: 3M | D5: MMM | E5: 449000000 | F5: 1706000000 | G5: 1389000000 | H5: 1814000000 | I5: 4246000000 | J5: 1983000000 | K5: 1983000000 | L5: -141000000 | M5: 316000000 | N5: 8583000000 | O5: 6600000000 | P5: 4337000000 | Q5: -277000000 | R5: 1390000000 | S5: 1389000000 | W5: =Raw_Data!C4&"|"&Raw_Data!D4&"|"&TEXT(Raw_Data!B4,"yyyy-mm-dd") -> 3M|MMM|2021-03-31
A6: 4 | B6: 44469 | C6: 3M | D6: MMM | E6: 482000000 | F6: 1761000000 | G6: 1434000000 | H6: 1739000000 | I6: 4089000000 | J6: 1868000000 | K6: 1868000000 | L6: -117000000 | M6: 324000000 | N6: 8942000000 | O6: 7074000000 | P6: 4853000000 | Q6: -107000000 | R6: 1437000000 | S6: 1434000000 | W6: =Raw_Data!C5&"|"&Raw_Data!D5&"|"&TEXT(Raw_Data!B5,"yyyy-mm-dd") -> 3M|MMM|2020-12-31
A7: 5 | B7: 44377 | C7: 3M | D7: MMM | E7: 514000000 | F7: 1940000000 | G7: 1524000000 | H7: 1666000000 | I7: 4231000000 | J7: 2051000000 | K7: 2051000000 | L7: -121000000 | M7: 415000000 | N7: 8950000000 | O7: 6899000000 | P7: 4719000000 | Q7: -111000000 | R7: 1525000000 | S7: 1524000000 | W7: =Raw_Data!C6&"|"&Raw_Data!D6&"|"&TEXT(Raw_Data!B6,"yyyy-mm-dd") -> 3M|MMM|2021-09-30
A8: 6 | B8: 44286 | C8: 3M | D8: MMM | E8: 520000000 | F8: 1946000000 | G8: 1624000000 | H8: 1720000000 | I8: 4327000000 | J8: 2087000000 | K8: 2087000000 | L8: -132000000 | M8: 319000000 | N8: 8851000000 | O8: 6764000000 | P8: 4524000000 | Q8: -141000000 | R8: 1627000000 | S8: 1624000000 | W8: =Raw_Data!C7&"|"&Raw_Data!D7&"|"&TEXT(Raw_Data!B7,"yyyy-mm-dd") -> 3M|MMM|2021-06-30
A9: 7 | B9: 44196 | C9: 3M | D9: MMM | E9: 449000000 | F9: 1706000000 | G9: 1389000000 | H9: 1814000000 | I9: 4246000000 | J9: 1983000000 | K9: 1983000000 | L9: -141000000 | M9: 316000000 | N9: 8583000000 | O9: 6600000000 | P9: 4337000000 | Q9: -277000000 | R9: 1390000000 | S9: 1389000000 | W9: =Raw_Data!C8&"|"&Raw_Data!D8&"|"&TEXT(Raw_Data!B8,"yyyy-mm-dd") -> 3M|MMM|2021-03-31
A10: 8 | B10: 44469 | C10: A. O. Smith | D10: AOS | F10: 166400000 | G10: 131600000 | H10: 174300000 | I10: 340300000 | J10: 166000000 | K10: 166000000 | L10: -1000000 | M10: 34800000 | N10: 914600000 | O10: 748600000 | P10: 574300000 | Q10: 400000 | R10: 131600000 | S10: 131600000 | W10: =Raw_Data!C9&"|"&Raw_Data!D9&"|"&TEXT(Raw_Data!B9,"yyyy-mm-dd") -> 3M|MMM|2020-12-31
A11: 9 | B11: 44377 | C11: A. O. Smith | D11: AOS | F11: 151300000 | G11: 118200000 | H11: 169800000 | I11: 321400000 | J11: 151600000 | K11: 151600000 | L11: -900000 | M11: 33100000 | N11: 859800000 | O11: 708200000 | P11: 538400000 | Q11: -300000 | R11: 118200000 | S11: 118200000 | W11: =Raw_Data!C10&"|"&Raw_Data!D10&"|"&TEXT(Raw_Data!B10,"yyyy-mm-dd") -> A. O. Smith|AOS|2021-09-30
A12: 10 | B12: 44286 | C12: A. O. Smith | D12: AOS | F12: 126100000 | G12: 97700000 | H12: 166500000 | I12: 288600000 | J12: 122100000 | K12: 122100000 | L12: -1000000 | M12: 28400000 | N12: 769000000 | O12: 646900000 | P12: 480400000 | Q12: 4000000 | R12: 97700000 | S12: 97700000 | W12: =Raw_Data!C11&"|"&Raw_Data!D11&"|"&TEXT(Raw_Data!B11,"yyyy-mm-dd") -> A. O. Smith|AOS|2021-06-30
A13: 11 | B13: 44196 | C13: A. O. Smith | D13: AOS | F13: 151900000 | G13: 120000000 | H13: 184700000 | I13: 324100000 | J13: 139400000 | K13: 139400000 | L13: -1000000 | M13: 31900000 | N13: 834500000 | O13: 695100000 | P13: 510400000 | Q13: 12500000 | R13: 120000000 | S13: 120000000 | W13: =Raw_Data!C12&"|"&Raw_Data!D12&"|"&TEXT(Raw_Data!B12,"yyyy-mm-dd") -> A. O. Smith|AOS|2021-03-31
A14: 12 | B14: 44469 | C14: Abbott Laboratories | D14: ABT | E14: 672000000 | F14: 2493000000 | G14: 2100000000 | H14: 2699000000 | I14: 6505000000 | J14: 2614000000 | K14: 2614000000 | L14: -133000000 | M14: 393000000 | N14: 10928000000 | O14: 8314000000 | P14: 4423000000 | Q14: -121000000 | R14: 2100000000 | S14: 2092000000 | W14: =Raw_Data!C13&"|"&Raw_Data!D13&"|"&TEXT(Raw_Data!B13,"yyyy-mm-dd") -> A. O. Smith|AOS|2020-12-31
A15: 13 | B15: 44377 | C15: Abbott Laboratories | D15: ABT | E15: 654000000 | F15: 1348000000 | G15: 1189000000 | H15: 2658000000 | I15: 5786000000 | J15: 1970000000 | K15: 1970000000 | L15: -134000000 | M15: 159000000 | N15: 10223000000 | O15: 8253000000 | P15: 4437000000 | Q15: -622000000 | R15: 1189000000 | S15: 1184000000 | W15: =Raw_Data!C14&"|"&Raw_Data!D14&"|"&TEXT(Raw_Data!B14,"yyyy-mm-dd") -> Abbott Laboratories|ABT|2021-09-30
A16: 14 | B16: 44286 | C16: Abbott Laboratories | D16: ABT | E16: 654000000 | F16: 2043000000 | G16: 1793000000 | H16: 2716000000 | I16: 6056000000 | J16: 2177000000 | K16: 2177000000 | L16: -135000000 | M16: 250000000 | N16: 10456000000 | O16: 8279000000 | P16: 4400000000 | Q16: -134000000 | R16: 1793000000 | S16: 1785000000 | W16: =Raw_Data!C15&"|"&Raw_Data!D15&"|"&TEXT(Raw_Data!B15,"yyyy-mm-dd") -> Abbott Laboratories|ABT|2021-06-30
A17: 15 | B17: 44196 | C17: Abbott Laboratories | D17: ABT | E17: 643000000 | F17: 2388000000 | G17: 2162000000 | H17: 2525000000 | I17: 6207000000 | J17: 2531000000 | K17: 2531000000 | L17: -136000000 | M17: 230000000 | N17: 10701000000 | O17: 8170000000 | P17: 4494000000 | Q17: -143000000 | R17: 2158000000 | S17: 2151000000 | W17: =Raw_Data!C16&"|"&Raw_Data!D16&"|"&TEXT(Raw_Data!B16,"yyyy-mm-dd") -> Abbott Laboratories|ABT|2021-03-31
A18: 16 | B18: 44469 | C18: AbbVie | D18: ABBV | E18: 1655000000 | F18: 3688000000 | G18: 3179000000 | H18: 2946000000 | I18: 9998000000 | J18: 4897000000 | K18: 4897000000 | L18: -596000000 | M18: 508000000 | N18: 14342000000 | O18: 9445000000 | P18: 4344000000 | Q18: -1209000000 | R18: 3180000000 | S18: 3158000000 | W18: =Raw_Data!C17&"|"&Raw_Data!D17&"|"&TEXT(Raw_Data!B17,"yyyy-mm-dd") -> Abbott Laboratories|ABT|2020-12-31
A19: 17 | B19: 44377 | C19: AbbVie | D19: ABBV | E19: 1784000000 | F19: 1163000000 | G19: 766000000 | H19: 3049000000 | I19: 9461000000 | J19: 4696000000 | K19: 4696000000 | L19: -615000000 | M19: 394000000 | N19: 13959000000 | O19: 9263000000 | P19: 4498000000 | Q19: -3533000000 | R19: 769000000 | S19: 751000000 | W19: =Raw_Data!C18&"|"&Raw_Data!D18&"|"&TEXT(Raw_Data!B18,"yyyy-mm-dd") -> AbbVie|ABBV|2021-09-30
A20: 18 | B20: 44286 | C20: AbbVie | D20: ABBV | E20: 1731000000 | F20: 3867000000 | G20: 3553000000 | H20: 2741000000 | I20: 8818000000 | J20: 4346000000 | K20: 4346000000 | L20: -632000000 | M20: 312000000 | N20: 13010000000 | O20: 8664000000 | P20: 4192000000 | Q20: -479000000 | R20: 3555000000 | S20: 3536000000 | W20: =Raw_Data!C19&"|"&Raw_Data!D19&"|"&TEXT(Raw_Data!B19,"yyyy-mm-dd") -> AbbVie|ABBV|2021-06-30
A21: 19 | B21: 44196 | C21: AbbVie | D21: ABBV | E21: 1821000000 | F21: -1507000000 | G21: 36000000 | H21: 3099000000 | I21: 10448000000 | J21: 5528000000 | K21: 5528000000 | L21: -629000000 | M21: -1545000000 | N21: 13858000000 | O21: 8330000000 | P21: 3410000000 | Q21: -7035000000 | R21: 38000000 | S21: 20000000 | W21: =Raw_Data!C20&"|"&Raw_Data!D20&"|"&TEXT(Raw_Data!B20,"yyyy-mm-dd") -> AbbVie|ABBV|2021-03-31
A22: 20 | B22: 44469 | C22: Abiomed | D22: ABMD | E22: 41041000 | F22: 67271000 | G22: 56953000 | H22: 102779000 | I22: 204256000 | J22: 60436000 | K22: 60436000 | M22: 10318000 | N22: 248142000 | O22: 187706000 | P22: 43886000 | Q22: 6835000 | R22: 56953000 | S22: 56953000 | W22: =Raw_Data!C21&"|"&Raw_Data!D21&"|"&TEXT(Raw_Data!B21,"yyyy-mm-dd") -> AbbVie|ABBV|2020-12-31
A23: 21 | B23: 44377 | C23: Abiomed | D23: ABMD | E23: 36837000 | F23: -9350000 | G23: -26525000 | H23: 103484000 | I23: 207397000 | J23: 67076000 | K23: 67076000 | M23: 17175000 | N23: 252585000 | O23: 185509000 | P23: 45188000 | Q23: -76426000 | R23: -26525000 | S23: -26525000 | W23: =Raw_Data!C22&"|"&Raw_Data!D22&"|"&TEXT(Raw_Data!B22,"yyyy-mm-dd") -> Abiomed|ABMD|2021-09-30
A24: 22 | B24: 44286 | C24: Abiomed | D24: ABMD | E24: 32599000 | F24: 73494000 | G24: 56856000 | H24: 100374000 | I24: 195167000 | J24: 62194000 | K24: 62194000 | M24: 16638000 | N24: 241245000 | O24: 179051000 | P24: 46078000 | Q24: 11300000 | R24: 56856000 | S24: 56856000 | W24: =Raw_Data!C23&"|"&Raw_Data!D23&"|"&TEXT(Raw_Data!B23,"yyyy-mm-dd") -> Abiomed|ABMD|2021-06-30
A25: 23 | B25: 44196 | C25: Abiomed | D25: ABMD | E25: 32105000 | F25: 80735000 | G25: 61868000 | H25: 86198000 | I25: 190553000 | J25: 72250000 | K25: 72250000 | M25: 18867000 | N25: 231663000 | O25: 159413000 | P25: 41110000 | Q25: 8485000 | R25: 61868000 | S25: 61868000 | W25: =Raw_Data!C24&"|"&Raw_Data!D24&"|"&TEXT(Raw_Data!B24,"yyyy-mm-dd") -> Abiomed|ABMD|2021-03-31
A26: 24 | B26: 44439 | C26: Accenture | D26: ACN | F26: 1917805000 | G26: 1416248000 | H26: 2507527000 | I26: 4466216000 | J26: 1958689000 | K26: 1958689000 | L26: -12977000 | M26: 480382000 | N26: 13419284000 | O26: 11460595000 | P26: 8953068000 | Q26: -40884000 | R26: 1437423000 | S26: 1416248000 | W26: =Raw_Data!C25&"|"&Raw_Data!D25&"|"&TEXT(Raw_Data!B25,"yyyy-mm-dd") -> Abiomed|ABMD|2020-12-31
A27: 25 | B27: 44347 | C27: Accenture | D27: ACN | F27: 2094001000 | G27: 1549426000 | H27: 2285728000 | I27: 4404384000 | J27: 2118656000 | K27: 2118656000 | L27: -28739000 | M27: 524429000 | N27: 13263795000 | O27: 11145139000 | P27: 8859411000 | Q27: -24655000 | R27: 1569572000 | S27: 1549426000 | W27: =Raw_Data!C26&"|"&Raw_Data!D26&"|"&TEXT(Raw_Data!B26,"yyyy-mm-dd") -> Accenture|ACN|2021-08-31
A28: 26 | B28: 44255 | C28: Accenture | D28: ACN | F28: 1762443000 | G28: 1440859000 | H28: 1941717000 | I28: 3595232000 | J28: 1653515000 | K28: 1653515000 | L28: -8922000 | M28: 300950000 | N28: 12088125000 | O28: 10434610000 | P28: 8492893000 | Q28: 108928000 | R28: 1461493000 | S28: 1440859000 | W28: =Raw_Data!C27&"|"&Raw_Data!D27&"|"&TEXT(Raw_Data!B27,"yyyy-mm-dd") -> Accenture|ACN|2021-05-31
A29: 27 | B29: 44165 | C29: Accenture | D29: ACN | F29: 1986867000 | G29: 1500276000 | H29: 2007627000 | I29: 3898296000 | J29: 1890669000 | K29: 1890669000 | L29: -8854000 | M29: 464810000 | N29: 11762185000 | O29: 9871516000 | P29: 7863889000 | Q29: 96198000 | R29: 1522057000 | S29: 1500276000 | W29: =Raw_Data!C28&"|"&Raw_Data!D28&"|"&TEXT(Raw_Data!B28,"yyyy-mm-dd") -> Accenture|ACN|2021-02-28
A30: 28 | B30: 44469 | C30: Activision Blizzard | D30: ATVI | E30: 329000000 | F30: 759000000 | G30: 639000000 | H30: 387000000 | I30: 1543000000 | J30: 827000000 | K30: 827000000 | L30: -27000000 | M30: 120000000 | N30: 2070000000 | O30: 1243000000 | P30: 527000000 | Q30: -68000000 | R30: 639000000 | S30: 639000000 | W30: =Raw_Data!C29&"|"&Raw_Data!D29&"|"&TEXT(Raw_Data!B29,"yyyy-mm-dd") -> Accenture|ACN|2020-11-30
A31: 29 | B31: 44377 | C31: Activision Blizzard | D31: ATVI | E31: 335000000 | F31: 1002000000 | G31: 876000000 | H31: 434000000 | I31: 1741000000 | J31: 972000000 | K31: 972000000 | L31: -27000000 | M31: 126000000 | N31: 2296000000 | O31: 1324000000 | P31: 555000000 | Q31: 30000000 | R31: 876000000 | S31: 876000000 | W31: =Raw_Data!C30&"|"&Raw_Data!D30&"|"&TEXT(Raw_Data!B30,"yyyy-mm-dd") -> Activision Blizzard|ATVI|2021-09-30
A32: 30 | B32: 44286 | C32: Activision Blizzard | D32: ATVI | E32: 353000000 | F32: 765000000 | G32: 619000000 | H32: 519000000 | I32: 1697000000 | J32: 825000000 | K32: 825000000 | L32: -28000000 | M32: 146000000 | N32: 2275000000 | O32: 1450000000 | P32: 578000000 | Q32: -60000000 | R32: 619000000 | S32: 619000000 | W32: =Raw_Data!C31&"|"&Raw_Data!D31&"|"&TEXT(Raw_Data!B31,"yyyy-mm-dd") -> Activision Blizzard|ATVI|2021-06-30
A33: 31 | B33: 44196 | C33: Activision Blizzard | D33: ATVI | E33: 348000000 | F33: 563000000 | G33: 509000000 | H33: 597000000 | I33: 1595000000 | J33: 650000000 | K33: 650000000 | L33: -27000000 | M33: 54000000 | N33: 2412000000 | O33: 1762000000 | P33: 817000000 | Q33: -87000000 | R33: 509000000 | S33: 509000000 | W33: =Raw_Data!C32&"|"&Raw_Data!D32&"|"&TEXT(Raw_Data!B32,"yyyy-mm-dd") -> Activision Blizzard|ATVI|2021-03-31
A34: 32 | B34: 44469 | C34: ADM | D34: ADM | F34: 653000000 | G34: 526000000 | H34: 716000000 | I34: 1326000000 | J34: 607000000 | K34: 607000000 | L34: -61000000 | M34: 120000000 | N34: 20340000000 | O34: 19733000000 | P34: 19014000000 | Q34: 46000000 | R34: 533000000 | S34: 526000000 | W34: =Raw_Data!C33&"|"&Raw_Data!D33&"|"&TEXT(Raw_Data!B33,"yyyy-mm-dd") -> Activision Blizzard|ATVI|2020-12-31
A35: 33 | B35: 44377 | C35: ADM | D35: ADM | F35: 825000000 | G35: 712000000 | H35: 815000000 | I35: 1463000000 | J35: 642000000 | K35: 642000000 | L35: -40000000 | M35: 113000000 | N35: 22926000000 | O35: 22284000000 | P35: 21463000000 | Q35: 183000000 | R35: 712000000 | S35: 712000000 | W35: =Raw_Data!C34&"|"&Raw_Data!D34&"|"&TEXT(Raw_Data!B34,"yyyy-mm-dd") -> ADM|ADM|2021-09-30
A36: 34 | B36: 44286 | C36: ADM | D36: ADM | F36: 824000000 | G36: 689000000 | H36: 697000000 | I36: 1548000000 | J36: 843000000 | K36: 843000000 | L36: -87000000 | M36: 131000000 | N36: 18893000000 | O36: 18050000000 | P36: 17345000000 | Q36: -19000000 | R36: 693000000 | S36: 689000000 | W36: =Raw_Data!C35&"|"&Raw_Data!D35&"|"&TEXT(Raw_Data!B35,"yyyy-mm-dd") -> ADM|ADM|2021-06-30
A37: 35 | B37: 44196 | C37: ADM | D37: ADM | F37: 756000000 | G37: 687000000 | H37: 720000000 | I37: 1352000000 | J37: 615000000 | K37: 615000000 | L37: -69000000 | M37: 63000000 | N37: 17978000000 | O37: 17363000000 | P37: 16626000000 | Q37: 141000000 | R37: 693000000 | S37: 687000000 | W37: =Raw_Data!C36&"|"&Raw_Data!D36&"|"&TEXT(Raw_Data!B36,"yyyy-mm-dd") -> ADM|ADM|2021-03-31
A38: 36 | B38: 44442 | C38: Adobe | D38: ADBE | E38: 651000000 | F38: 1418000000 | G38: 1212000000 | H38: 1333000000 | I38: 3468000000 | J38: 1441000000 | K38: 1441000000 | L38: -27000000 | M38: 206000000 | N38: 3935000000 | O38: 2494000000 | P38: 467000000 | Q38: -23000000 | R38: 1212000000 | S38: 1212000000 | W38: =Raw_Data!C37&"|"&Raw_Data!D37&"|"&TEXT(Raw_Data!B37,"yyyy-mm-dd") -> ADM|ADM|2020-12-31
A39: 37 | B39: 44351 | C39: Adobe | D39: ADBE | E39: 612000000 | F39: 1386000000 | G39: 1116000000 | H39: 1329000000 | I39: 3391000000 | J39: 1406000000 | K39: 1406000000 | L39: -28000000 | M39: 270000000 | N39: 3835000000 | O39: 2429000000 | P39: 444000000 | Q39: -20000000 | R39: 1116000000 | S39: 1116000000 | W39: =Raw_Data!C38&"|"&Raw_Data!D38&"|"&TEXT(Raw_Data!B38,"yyyy-mm-dd") -> Adobe|ADBE|2021-09-03
A40: 38 | B40: 44260 | C40: Adobe | D40: ADBE | E40: 620000000 | F40: 1433000000 | G40: 1261000000 | H40: 1339000000 | I40: 3458000000 | J40: 1454000000 | K40: 1454000000 | L40: -30000000 | M40: 172000000 | N40: 3905000000 | O40: 2451000000 | P40: 447000000 | Q40: -21000000 | R40: 1261000000 | S40: 1261000000 | W40: =Raw_Data!C39&"|"&Raw_Data!D39&"|"&TEXT(Raw_Data!B39,"yyyy-mm-dd") -> Adobe|ADBE|2021-06-04
...

Sheet Cleaned_Data
A1: S. NO. | B1: date | C1: firm | D1: Ticker | E1: Research Development | F1: Income Before Tax | G1: Net Income | H1: Selling General Administrative | I1: Gross Profit | J1: Ebit | K1: Operating Income | L1: Interest Expense | M1: Income Tax Expense | N1: Total Revenue | O1: Total Operating Expenses | P1: Cost Of Revenue | Q1: Total Other Income Expense Net | R1: Net Income From Continuing Ops | S1: Net Income Applicable To Common Shares
A2: 0 | B2: 44469 | C2: 3M | D2: MMM | E2: 482000000 | F2: 1761000000 | G2: 1434000000 | H2: 1739000000 | I2: 4089000000 | J2: 1868000000 | K2: 1868000000 | L2: -117000000 | M2: 324000000 | N2: 8942000000 | O2: 7074000000 | P2: 4853000000 | Q2: -107000000 | R2: 1437000000 | S2: 1434000000
A3: 1 | B3: 44377 | C3: 3M | D3: MMM | E3: 514000000 | F3: 1940000000 | G3: 1524000000 | H3: 1666000000 | I3: 4231000000 | J3: 2051000000 | K3: 2051000000 | L3: -121000000 | M3: 415000000 | N3: 8950000000 | O3: 6899000000 | P3: 4719000000 | Q3: -111000000 | R3: 1525000000 | S3: 1524000000
A4: 2 | B4: 44286 | C4: 3M | D4: MMM | E4: 520000000 | F4: 1946000000 | G4: 1624000000 | H4: 1720000000 | I4: 4327000000 | J4: 2087000000 | K4: 2087000000 | L4: -132000000 | M4: 319000000 | N4: 8851000000 | O4: 6764000000 | P4: 4524000000 | Q4: -141000000 | R4: 1627000000 | S4: 1624000000
A5: 3 | B5: 44196 | C5: 3M | D5: MMM | E5: 449000000 | F5: 1706000000 | G5: 1389000000 | H5: 1814000000 | I5: 4246000000 | J5: 1983000000 | K5: 1983000000 | L5: -141000000 | M5: 316000000 | N5: 8583000000 | O5: 6600000000 | P5: 4337000000 | Q5: -277000000 | R5: 1390000000 | S5: 1389000000
A6: 4 | B6: 44469 | C6: 3M | D6: MMM | E6: 482000000 | F6: 1761000000 | G6: 1434000000 | H6: 1739000000 | I6: 4089000000 | J6: 1868000000 | K6: 1868000000 | L6: -117000000 | M6: 324000000 | N6: 8942000000 | O6: 7074000000 | P6: 4853000000 | Q6: -107000000 | R6: 1437000000 | S6: 1434000000
A7: 5 | B7: 44377 | C7: 3M | D7: MMM | E7: 514000000 | F7: 1940000000 | G7: 1524000000 | H7: 1666000000 | I7: 4231000000 | J7: 2051000000 | K7: 2051000000 | L7: -121000000 | M7: 415000000 | N7: 8950000000 | O7: 6899000000 | P7: 4719000000 | Q7: -111000000 | R7: 1525000000 | S7: 1524000000
A8: 6 | B8: 44286 | C8: 3M | D8: MMM | E8: 520000000 | F8: 1946000000 | G8: 1624000000 | H8: 1720000000 | I8: 4327000000 | J8: 2087000000 | K8: 2087000000 | L8: -132000000 | M8: 319000000 | N8: 8851000000 | O8: 6764000000 | P8: 4524000000 | Q8: -141000000 | R8: 1627000000 | S8: 1624000000
A9: 7 | B9: 44196 | C9: 3M | D9: MMM | E9: 449000000 | F9: 1706000000 | G9: 1389000000 | H9: 1814000000 | I9: 4246000000 | J9: 1983000000 | K9: 1983000000 | L9: -141000000 | M9: 316000000 | N9: 8583000000 | O9: 6600000000 | P9: 4337000000 | Q9: -277000000 | R9: 1390000000 | S9: 1389000000
A10: 8 | B10: 44469 | C10: A. O. Smith | D10: AOS | F10: 166400000 | G10: 131600000 | H10: 174300000 | I10: 340300000 | J10: 166000000 | K10: 166000000 | L10: -1000000 | M10: 34800000 | N10: 914600000 | O10: 748600000 | P10: 574300000 | Q10: 400000 | R10: 131600000 | S10: 131600000
A11: 9 | B11: 44377 | C11: A. O. Smith | D11: AOS | F11: 151300000 | G11: 118200000 | H11: 169800000 | I11: 321400000 | J11: 151600000 | K11: 151600000 | L11: -900000 | M11: 33100000 | N11: 859800000 | O11: 708200000 | P11: 538400000 | Q11: -300000 | R11: 118200000 | S11: 118200000
A12: 10 | B12: 44286 | C12: A. O. Smith | D12: AOS | F12: 126100000 | G12: 97700000 | H12: 166500000 | I12: 288600000 | J12: 122100000 | K12: 122100000 | L12: -1000000 | M12: 28400000 | N12: 769000000 | O12: 646900000 | P12: 480400000 | Q12: 4000000 | R12: 97700000 | S12: 97700000
A13: 11 | B13: 44196 | C13: A. O. Smith | D13: AOS | F13: 151900000 | G13: 120000000 | H13: 184700000 | I13: 324100000 | J13: 139400000 | K13: 139400000 | L13: -1000000 | M13: 31900000 | N13: 834500000 | O13: 695100000 | P13: 510400000 | Q13: 12500000 | R13: 120000000 | S13: 120000000
A14: 12 | B14: 44469 | C14: Abbott Laboratories | D14: ABT | E14: 672000000 | F14: 2493000000 | G14: 2100000000 | H14: 2699000000 | I14: 6505000000 | J14: 2614000000 | K14: 2614000000 | L14: -133000000 | M14: 393000000 | N14: 10928000000 | O14: 8314000000 | P14: 4423000000 | Q14: -121000000 | R14: 2100000000 | S14: 2092000000
A15: 13 | B15: 44377 | C15: Abbott Laboratories | D15: ABT | E15: 654000000 | F15: 1348000000 | G15: 1189000000 | H15: 2658000000 | I15: 5786000000 | J15: 1970000000 | K15: 1970000000 | L15: -134000000 | M15: 159000000 | N15: 10223000000 | O15: 8253000000 | P15: 4437000000 | Q15: -622000000 | R15: 1189000000 | S15: 1184000000
A16: 14 | B16: 44286 | C16: Abbott Laboratories | D16: ABT | E16: 654000000 | F16: 2043000000 | G16: 1793000000 | H16: 2716000000 | I16: 6056000000 | J16: 2177000000 | K16: 2177000000 | L16: -135000000 | M16: 250000000 | N16: 10456000000 | O16: 8279000000 | P16: 4400000000 | Q16: -134000000 | R16: 1793000000 | S16: 1785000000
A17: 15 | B17: 44196 | C17: Abbott Laboratories | D17: ABT | E17: 643000000 | F17: 2388000000 | G17: 2162000000 | H17: 2525000000 | I17: 6207000000 | J17: 2531000000 | K17: 2531000000 | L17: -136000000 | M17: 230000000 | N17: 10701000000 | O17: 8170000000 | P17: 4494000000 | Q17: -143000000 | R17: 2158000000 | S17: 2151000000
A18: 16 | B18: 44469 | C18: AbbVie | D18: ABBV | E18: 1655000000 | F18: 3688000000 | G18: 3179000000 | H18: 2946000000 | I18: 9998000000 | J18: 4897000000 | K18: 4897000000 | L18: -596000000 | M18: 508000000 | N18: 14342000000 | O18: 9445000000 | P18: 4344000000 | Q18: -1209000000 | R18: 3180000000 | S18: 3158000000
A19: 17 | B19: 44377 | C19: AbbVie | D19: ABBV | E19: 1784000000 | F19: 1163000000 | G19: 766000000 | H19: 3049000000 | I19: 9461000000 | J19: 4696000000 | K19: 4696000000 | L19: -615000000 | M19: 394000000 | N19: 13959000000 | O19: 9263000000 | P19: 4498000000 | Q19: -3533000000 | R19: 769000000 | S19: 751000000
A20: 18 | B20: 44286 | C20: AbbVie | D20: ABBV | E20: 1731000000 | F20: 3867000000 | G20: 3553000000 | H20: 2741000000 | I20: 8818000000 | J20: 4346000000 | K20: 4346000000 | L20: -632000000 | M20: 312000000 | N20: 13010000000 | O20: 8664000000 | P20: 4192000000 | Q20: -479000000 | R20: 3555000000 | S20: 3536000000
A21: 19 | B21: 44196 | C21: AbbVie | D21: ABBV | E21: 1821000000 | F21: -1507000000 | G21: 36000000 | H21: 3099000000 | I21: 10448000000 | J21: 5528000000 | K21: 5528000000 | L21: -629000000 | M21: -1545000000 | N21: 13858000000 | O21: 8330000000 | P21: 3410000000 | Q21: -7035000000 | R21: 38000000 | S21: 20000000
A22: 20 | B22: 44469 | C22: Abiomed | D22: ABMD | E22: 41041000 | F22: 67271000 | G22: 56953000 | H22: 102779000 | I22: 204256000 | J22: 60436000 | K22: 60436000 | M22: 10318000 | N22: 248142000 | O22: 187706000 | P22: 43886000 | Q22: 6835000 | R22: 56953000 | S22: 56953000
A23: 21 | B23: 44377 | C23: Abiomed | D23: ABMD | E23: 36837000 | F23: -9350000 | G23: -26525000 | H23: 103484000 | I23: 207397000 | J23: 67076000 | K23: 67076000 | M23: 17175000 | N23: 252585000 | O23: 185509000 | P23: 45188000 | Q23: -76426000 | R23: -26525000 | S23: -26525000
A24: 22 | B24: 44286 | C24: Abiomed | D24: ABMD | E24: 32599000 | F24: 73494000 | G24: 56856000 | H24: 100374000 | I24: 195167000 | J24: 62194000 | K24: 62194000 | M24: 16638000 | N24: 241245000 | O24: 179051000 | P24: 46078000 | Q24: 11300000 | R24: 56856000 | S24: 56856000
A25: 23 | B25: 44196 | C25: Abiomed | D25: ABMD | E25: 32105000 | F25: 80735000 | G25: 61868000 | H25: 86198000 | I25: 190553000 | J25: 72250000 | K25: 72250000 | M25: 18867000 | N25: 231663000 | O25: 159413000 | P25: 41110000 | Q25: 8485000 | R25: 61868000 | S25: 61868000
A26: 24 | B26: 44439 | C26: Accenture | D26: ACN | F26: 1917805000 | G26: 1416248000 | H26: 2507527000 | I26: 4466216000 | J26: 1958689000 | K26: 1958689000 | L26: -12977000 | M26: 480382000 | N26: 13419284000 | O26: 11460595000 | P26: 8953068000 | Q26: -40884000 | R26: 1437423000 | S26: 1416248000
A27: 25 | B27: 44347 | C27: Accenture | D27: ACN | F27: 2094001000 | G27: 1549426000 | H27: 2285728000 | I27: 4404384000 | J27: 2118656000 | K27: 2118656000 | L27: -28739000 | M27: 524429000 | N27: 13263795000 | O27: 11145139000 | P27: 8859411000 | Q27: -24655000 | R27: 1569572000 | S27: 1549426000
A28: 26 | B28: 44255 | C28: Accenture | D28: ACN | F28: 1762443000 | G28: 1440859000 | H28: 1941717000 | I28: 3595232000 | J28: 1653515000 | K28: 1653515000 | L28: -8922000 | M28: 300950000 | N28: 12088125000 | O28: 10434610000 | P28: 8492893000 | Q28: 108928000 | R28: 1461493000 | S28: 1440859000
A29: 27 | B29: 44165 | C29: Accenture | D29: ACN | F29: 1986867000 | G29: 1500276000 | H29: 2007627000 | I29: 3898296000 | J29: 1890669000 | K29: 1890669000 | L29: -8854000 | M29: 464810000 | N29: 11762185000 | O29: 9871516000 | P29: 7863889000 | Q29: 96198000 | R29: 1522057000 | S29: 1500276000
A30: 28 | B30: 44469 | C30: Activision Blizzard | D30: ATVI | E30: 329000000 | F30: 759000000 | G30: 639000000 | H30: 387000000 | I30: 1543000000 | J30: 827000000 | K30: 827000000 | L30: -27000000 | M30: 120000000 | N30: 2070000000 | O30: 1243000000 | P30: 527000000 | Q30: -68000000 | R30: 639000000 | S30: 639000000
A31: 29 | B31: 44377 | C31: Activision Blizzard | D31: ATVI | E31: 335000000 | F31: 1002000000 | G31: 876000000 | H31: 434000000 | I31: 1741000000 | J31: 972000000 | K31: 972000000 | L31: -27000000 | M31: 126000000 | N31: 2296000000 | O31: 1324000000 | P31: 555000000 | Q31: 30000000 | R31: 876000000 | S31: 876000000
A32: 30 | B32: 44286 | C32: Activision Blizzard | D32: ATVI | E32: 353000000 | F32: 765000000 | G32: 619000000 | H32: 519000000 | I32: 1697000000 | J32: 825000000 | K32: 825000000 | L32: -28000000 | M32: 146000000 | N32: 2275000000 | O32: 1450000000 | P32: 578000000 | Q32: -60000000 | R32: 619000000 | S32: 619000000
A33: 31 | B33: 44196 | C33: Activision Blizzard | D33: ATVI | E33: 348000000 | F33: 563000000 | G33: 509000000 | H33: 597000000 | I33: 1595000000 | J33: 650000000 | K33: 650000000 | L33: -27000000 | M33: 54000000 | N33: 2412000000 | O33: 1762000000 | P33: 817000000 | Q33: -87000000 | R33: 509000000 | S33: 509000000
A34: 32 | B34: 44469 | C34: ADM | D34: ADM | F34: 653000000 | G34: 526000000 | H34: 716000000 | I34: 1326000000 | J34: 607000000 | K34: 607000000 | L34: -61000000 | M34: 120000000 | N34: 20340000000 | O34: 19733000000 | P34: 19014000000 | Q34: 46000000 | R34: 533000000 | S34: 526000000
A35: 33 | B35: 44377 | C35: ADM | D35: ADM | F35: 825000000 | G35: 712000000 | H35: 815000000 | I35: 1463000000 | J35: 642000000 | K35: 642000000 | L35: -40000000 | M35: 113000000 | N35: 22926000000 | O35: 22284000000 | P35: 21463000000 | Q35: 183000000 | R35: 712000000 | S35: 712000000
A36: 34 | B36: 44286 | C36: ADM | D36: ADM | F36: 824000000 | G36: 689000000 | H36: 697000000 | I36: 1548000000 | J36: 843000000 | K36: 843000000 | L36: -87000000 | M36: 131000000 | N36: 18893000000 | O36: 18050000000 | P36: 17345000000 | Q36: -19000000 | R36: 693000000 | S36: 689000000
A37: 35 | B37: 44196 | C37: ADM | D37: ADM | F37: 756000000 | G37: 687000000 | H37: 720000000 | I37: 1352000000 | J37: 615000000 | K37: 615000000 | L37: -69000000 | M37: 63000000 | N37: 17978000000 | O37: 17363000000 | P37: 16626000000 | Q37: 141000000 | R37: 693000000 | S37: 687000000
A38: 36 | B38: 44442 | C38: Adobe | D38: ADBE | E38: 651000000 | F38: 1418000000 | G38: 1212000000 | H38: 1333000000 | I38: 3468000000 | J38: 1441000000 | K38: 1441000000 | L38: -27000000 | M38: 206000000 | N38: 3935000000 | O38: 2494000000 | P38: 467000000 | Q38: -23000000 | R38: 1212000000 | S38: 1212000000
A39: 37 | B39: 44351 | C39: Adobe | D39: ADBE | E39: 612000000 | F39: 1386000000 | G39: 1116000000 | H39: 1329000000 | I39: 3391000000 | J39: 1406000000 | K39: 1406000000 | L39: -28000000 | M39: 270000000 | N39: 3835000000 | O39: 2429000000 | P39: 444000000 | Q39: -20000000 | R39: 1116000000 | S39: 1116000000
A40: 38 | B40: 44260 | C40: Adobe | D40: ADBE | E40: 620000000 | F40: 1433000000 | G40: 1261000000 | H40: 1339000000 | I40: 3458000000 | J40: 1454000000 | K40: 1454000000 | L40: -30000000 | M40: 172000000 | N40: 3905000000 | O40: 2451000000 | P40: 447000000 | Q40: -21000000 | R40: 1261000000 | S40: 1261000000
...

Sheet Financial_Analysis
A1: Metric | B1: Value | D1: Company Analysis | G1: Top 10 Companies | H1: Total Revenue | M1: =ISNUMBER(K24) -> FALSE
A2: Total Revenue | B2: =SUM(Cleaned_Data!N2:N2013) -> 13173344212500 | D2: Company | E2: Total Revenue | G2: =IFERROR(__xludf.DUMMYFUNCTION("SORTN(D3:E504,10,0,2,FALSE)"),"Walmart") -> Walmart | H2: =IFERROR(__xludf.DUMMYFUNCTION("""COMPUTED_VALUE"""),5.66145E11) -> 566145000000 | M2: =ISNUMBER(L24) -> FALSE
A3: Total Gross Profit | B3: =SUM(Cleaned_Data!I2:I2013) -> 5165530836500 | D3: {=UNIQUE(Cleaned_Data!C2:C2013)} -> 3M | E3: =SUMIF(Cleaned_Data!C$2:C$2013,D3,Cleaned_Data!N$2:N$2013) -> 70652000000 | G3: =IFERROR(__xludf.DUMMYFUNCTION("""COMPUTED_VALUE"""),"Amazon") -> Amazon | H3: =IFERROR(__xludf.DUMMYFUNCTION("""COMPUTED_VALUE"""),4.43298E11) -> 443298000000
A4: Total Operating Income | B4: =SUM(Cleaned_Data!K2:K2013) -> 2049131813000 | D4: A. O. Smith | E4: =SUMIF(Cleaned_Data!C$2:C$2013,D4,Cleaned_Data!N$2:N$2013) -> 3377900000 | G4: =IFERROR(__xludf.DUMMYFUNCTION("""COMPUTED_VALUE"""),"Apple") -> Apple | H4: =IFERROR(__xludf.DUMMYFUNCTION("""COMPUTED_VALUE"""),3.47155E11) -> 347155000000
A5: Total Net Income | B5: =SUM(Cleaned_Data!G2:G2013) -> 1441865680000 | D5: Abbott Laboratories | E5: =SUMIF(Cleaned_Data!C$2:C$2013,D5,Cleaned_Data!N$2:N$2013) -> 42308000000 | G5: =IFERROR(__xludf.DUMMYFUNCTION("""COMPUTED_VALUE"""),"CVS Health") -> CVS Health | H5: =IFERROR(__xludf.DUMMYFUNCTION("""COMPUTED_VALUE"""),2.77285E11) -> 277285000000
A6: Average Revenue | B6: =AVERAGE(Cleaned_Data!N2:N2013) -> 6547387780 | D6: AbbVie | E6: =SUMIF(Cleaned_Data!C$2:C$2013,D6,Cleaned_Data!N$2:N$2013) -> 55169000000 | G6: =IFERROR(__xludf.DUMMYFUNCTION("""COMPUTED_VALUE"""),"UnitedHealth Group") -> UnitedHealth Group | H6: =IFERROR(__xludf.DUMMYFUNCTION("""COMPUTED_VALUE"""),2.72099E11) -> 272099000000
A7: Median Revenue | B7: =MEDIAN(Cleaned_Data!N2:N2013) -> 2624661500 | D7: Abiomed | E7: =SUMIF(Cleaned_Data!C$2:C$2013,D7,Cleaned_Data!N$2:N$2013) -> 973635000 | G7: =IFERROR(__xludf.DUMMYFUNCTION("""COMPUTED_VALUE"""),"McKesson Corporation") -> McKesson Corporation | H7: =IFERROR(__xludf.DUMMYFUNCTION("""COMPUTED_VALUE"""),2.38228E11) -> 238228000000
D8: Accenture | E8: =SUMIF(Cleaned_Data!C$2:C$2013,D8,Cleaned_Data!N$2:N$2013) -> 50533389000 | G8: =IFERROR(__xludf.DUMMYFUNCTION("""COMPUTED_VALUE"""),"Alphabet (Class A)") -> Alphabet (Class A) | H8: =IFERROR(__xludf.DUMMYFUNCTION("""COMPUTED_VALUE"""),2.20265E11) -> 220265000000
A9: Profitability Metric | B9: Value | D9: Activision Blizzard | E9: =SUMIF(Cleaned_Data!C$2:C$2013,D9,Cleaned_Data!N$2:N$2013) -> 9053000000 | G9: =IFERROR(__xludf.DUMMYFUNCTION("""COMPUTED_VALUE"""),"Alphabet (Class C)") -> Alphabet (Class C) | H9: =IFERROR(__xludf.DUMMYFUNCTION("""COMPUTED_VALUE"""),2.20265E11) -> 220265000000
A10: Gross Profit Margin | B10: =B3/B2 -> 0.39211993 | D10: ADM | E10: =SUMIF(Cleaned_Data!C$2:C$2013,D10,Cleaned_Data!N$2:N$2013) -> 80137000000 | G10: =IFERROR(__xludf.DUMMYFUNCTION("""COMPUTED_VALUE"""),"ExxonMobil") -> ExxonMobil | H10: =IFERROR(__xludf.DUMMYFUNCTION("""COMPUTED_VALUE"""),2.15879E11) -> 215879000000
A11: Operating Margin | B11: =B4/B3 -> 0.39669337 | D11: Adobe | E11: =SUMIF(Cleaned_Data!C$2:C$2013,D11,Cleaned_Data!N$2:N$2013) -> 15099000000 | G11: =IFERROR(__xludf.DUMMYFUNCTION("""COMPUTED_VALUE"""),"AmerisourceBergen") -> AmerisourceBergen | H11: =IFERROR(__xludf.DUMMYFUNCTION("""COMPUTED_VALUE"""),2.0432119E11) -> 204321190000
A12: Net Profit Margin | B12: =B5/B4 -> 0.70364711 | D12: Advance Auto Parts | E12: =SUMIF(Cleaned_Data!C$2:C$2013,D12,Cleaned_Data!N$2:N$2013) -> 11619092500
D13: Advanced Micro Devices | E13: =SUMIF(Cleaned_Data!C$2:C$2013,D13,Cleaned_Data!N$2:N$2013) -> 14852000000
D14: AES Corp | E14: =SUMIF(Cleaned_Data!C$2:C$2013,D14,Cleaned_Data!N$2:N$2013) -> 10931000000
D15: Aflac | E15: =SUMIF(Cleaned_Data!C$2:C$2013,D15,Cleaned_Data!N$2:N$2013) -> 22583000000
A16: Metric | B16: 2020 | C16: 2021 | D16: Agilent Technologies | E16: =SUMIF(Cleaned_Data!C$2:C$2013,D16,Cleaned_Data!N$2:N$2013) -> 6142000000 | J16: J16 | K16: YoY Growth
A17: Total Revenue | B17: =SUMPRODUCT((YEAR(Cleaned_Data!$B$2:$B$2013)=2020)*Cleaned_Data!$N$2:$N$2013) -> 5602951341000 | C17: =SUMPRODUCT((YEAR(Cleaned_Data!$B$2:$B$2013)=2021)*Cleaned_Data!$N$2:$N$2013) -> 7570392871500 | D17: Air Products & Chemicals | E17: =SUMIF(Cleaned_Data!C$2:C$2013,D17,Cleaned_Data!N$2:N$2013) -> 10323000000 | J17: J17 | K17: =(C17-B17)/B17 -> 0.35114378
A18: Gross Profit | B18: =SUMPRODUCT((YEAR(Cleaned_Data!$B$2:$B$2013)=2020)*Cleaned_Data!$I$2:$I$2013) -> 2135633400000 | C18: =SUMPRODUCT((YEAR(Cleaned_Data!$B$2:$B$2013)=2021)*Cleaned_Data!$I$2:$I$2013) -> 3029897436500 | D18: Akamai Technologies | E18: =SUMIF(Cleaned_Data!C$2:C$2013,D18,Cleaned_Data!N$2:N$2013) -> 3402152000 | J18: J18 | K18: =(C18-B18)/B18 -> 0.41873481
A19: Operating Income | B19: =SUMPRODUCT((YEAR(Cleaned_Data!$B$2:$B$2013)=2020)*Cleaned_Data!$K$2:$K$2013) -> 781890796000 | C19: =SUMPRODUCT((YEAR(Cleaned_Data!$B$2:$B$2013)=2021)*Cleaned_Data!$K$2:$K$2013) -> 1267241017000 | D19: Alaska Air Group | E19: =SUMIF(Cleaned_Data!C$2:C$2013,D19,Cleaned_Data!N$2:N$2013) -> 3312900000 | J19: J19 | K19: =(C19-B19)/B19 -> 0.62073914
A20: Net Income | B20: =SUMPRODUCT((YEAR(Cleaned_Data!$B$2:$B$2013)=2020)*Cleaned_Data!$G$2:$G$2013) -> 476451314000 | C20: =SUMPRODUCT((YEAR(Cleaned_Data!$B$2:$B$2013)=2021)*Cleaned_Data!$G$2:$G$2013) -> 965414366000 | D20: Albemarle Corporation | E20: =SUMIF(Cleaned_Data!C$2:C$2013,D20,Cleaned_Data!N$2:N$2013) -> 5085000000 | J20: J20 | K20: =(C20-B20)/B20 -> 1.0262603
D21: Alexandria Real Estate Equities | E21: =SUMIF(Cleaned_Data!C$2:C$2013,D21,Cleaned_Data!N$2:N$2013) -> 2013777000
D22: Align Technology | E22: =SUMIF(Cleaned_Data!C$2:C$2013,D22,Cleaned_Data!N$2:N$2013) -> 3756005000
A23: Margin | B23: 2020 | C23: 2021 | D23: Allegion | E23: =SUMIF(Cleaned_Data!C$2:C$2013,D23,Cleaned_Data!N$2:N$2013) -> 2885500000 | J23: Financial_Analysis | O23: Company | P23: Operating Income | Q23: Revenue | R23: Operating Margin | T23: Company | U23: Operating Margin
A24: Gross Profit Margin | B24: =B18/B17 -> 0.38116223 | C24: =C18/C17 -> 0.40022988 | D24: Alliant Energy | E24: =SUMIF(Cleaned_Data!C$2:C$2013,D24,Cleaned_Data!N$2:N$2013) -> 3559000000 | J24: =IFERROR(__xludf.DUMMYFUNCTION("QUERY({Cleaned_Data!C2:C2013,Cleaned_Data!K2:K2013,Cleaned_Data!N2:N2013},""select Col1, sum(Col2), sum(Col3) where Col1 is not null group by Col1"",0)"),"") | K24: =IFERROR(__xludf.DUMMYFUNCTION("""COMPUTED_VALUE"""),"sum ") -> sum | L24: =IFERROR(__xludf.DUMMYFUNCTION("""COMPUTED_VALUE"""),"sum ") -> sum | M24: =IFERROR(K24*1/(L24*1),"") | O24: {=UNIQUE(Cleaned_Data!C2:C2013)} -> 3M | P24: =SUMIF(Cleaned_Data!C$2:C$2013,O24,Cleaned_Data!K$2:K$2013) -> 15978000000 | Q24: =SUMIF(Cleaned_Data!C$2:C$2013,O24,Cleaned_Data!N$2:N$2013) -> 70652000000 | R24: =IFERROR(P24/Q24,"") -> 0.22615071 | T24: =IFERROR(__xludf.DUMMYFUNCTION("SORTN(FILTER({O24:O525,R24:R525},Q24:Q525>1000000000),10,0,2,FALSE)"),"Visa") -> Visa | U24: =IFERROR(__xludf.DUMMYFUNCTION("""COMPUTED_VALUE"""),0.6476796043626087) -> 0.6476796
A25: Operating Margin | B25: =B19/B17 -> 0.13954981 | C25: =C19/C17 -> 0.16739435 | D25: Allstate Corp | E25: =SUMIF(Cleaned_Data!C$2:C$2013,D25,Cleaned_Data!N$2:N$2013) -> 49595000000 | J25: =IFERROR(__xludf.DUMMYFUNCTION("""COMPUTED_VALUE"""),"3M") -> 3M | K25: =IFERROR(__xludf.DUMMYFUNCTION("""COMPUTED_VALUE"""),1.5978E10) -> 15978000000 | L25: =IFERROR(__xludf.DUMMYFUNCTION("""COMPUTED_VALUE"""),7.0652E10) -> 70652000000 | O25: A. O. Smith | P25: =SUMIF(Cleaned_Data!C$2:C$2013,O25,Cleaned_Data!K$2:K$2013) -> 579100000 | Q25: =SUMIF(Cleaned_Data!C$2:C$2013,O25,Cleaned_Data!N$2:N$2013) -> 3377900000 | R25: =IFERROR(P25/Q25,"") -> 0.17143788 | T25: =IFERROR(__xludf.DUMMYFUNCTION("""COMPUTED_VALUE"""),"Verisign") -> Verisign | U25: =IFERROR(__xludf.DUMMYFUNCTION("""COMPUTED_VALUE"""),0.6463368259797753) -> 0.64633683
A26: Net Profit Margin | B26: =B20/B17 -> 0.085035776 | C26: =C20/C17 -> 0.127525 | D26: Alphabet (Class A) | E26: =SUMIF(Cleaned_Data!C$2:C$2013,D26,Cleaned_Data!N$2:N$2013) -> 220265000000 | J26: =IFERROR(__xludf.DUMMYFUNCTION("""COMPUTED_VALUE"""),"A. O. Smith") -> A. O. Smith | K26: =IFERROR(__xludf.DUMMYFUNCTION("""COMPUTED_VALUE"""),5.791E8) -> 579100000 | L26: =IFERROR(__xludf.DUMMYFUNCTION("""COMPUTED_VALUE"""),3.3779E9) -> 3377900000 | O26: Abbott Laboratories | P26: =SUMIF(Cleaned_Data!C$2:C$2013,O26,Cleaned_Data!K$2:K$2013) -> 9292000000 | Q26: =SUMIF(Cleaned_Data!C$2:C$2013,O26,Cleaned_Data!N$2:N$2013) -> 42308000000 | R26: =IFERROR(P26/Q26,"") -> 0.21962749 | T26: =IFERROR(__xludf.DUMMYFUNCTION("""COMPUTED_VALUE"""),"Discover Financial Services") -> Discover Financial Services | U26: =IFERROR(__xludf.DUMMYFUNCTION("""COMPUTED_VALUE"""),0.5950649111499862) -> 0.59506491
D27: Alphabet (Class C) | E27: =SUMIF(Cleaned_Data!C$2:C$2013,D27,Cleaned_Data!N$2:N$2013) -> 220265000000 | J27: =IFERROR(__xludf.DUMMYFUNCTION("""COMPUTED_VALUE"""),"ADM") -> ADM | K27: =IFERROR(__xludf.DUMMYFUNCTION("""COMPUTED_VALUE"""),2.707E9) -> 2707000000 | L27: =IFERROR(__xludf.DUMMYFUNCTION("""COMPUTED_VALUE"""),8.0137E10) -> 80137000000 | O27: AbbVie | P27: =SUMIF(Cleaned_Data!C$2:C$2013,O27,Cleaned_Data!K$2:K$2013) -> 19467000000 | Q27: =SUMIF(Cleaned_Data!C$2:C$2013,O27,Cleaned_Data!N$2:N$2013) -> 55169000000 | R27: =IFERROR(P27/Q27,"") -> 0.35286121 | T27: =IFERROR(__xludf.DUMMYFUNCTION("""COMPUTED_VALUE"""),"Synchrony Financial") -> Synchrony Financial | U27: =IFERROR(__xludf.DUMMYFUNCTION("""COMPUTED_VALUE"""),0.5730718004601041) -> 0.5730718
D28: Altria Group | E28: =SUMIF(Cleaned_Data!C$2:C$2013,D28,Cleaned_Data!N$2:N$2013) -> 21227000000 | J28: =IFERROR(__xludf.DUMMYFUNCTION("""COMPUTED_VALUE"""),"AES Corp") -> AES Corp | K28: =IFERROR(__xludf.DUMMYFUNCTION("""COMPUTED_VALUE"""),2.699E9) -> 2699000000 | L28: =IFERROR(__xludf.DUMMYFUNCTION("""COMPUTED_VALUE"""),1.0931E10) -> 10931000000 | O28: Abiomed | P28: =SUMIF(Cleaned_Data!C$2:C$2013,O28,Cleaned_Data!K$2:K$2013) -> 261956000 | Q28: =SUMIF(Cleaned_Data!C$2:C$2013,O28,Cleaned_Data!N$2:N$2013) -> 973635000 | R28: =IFERROR(P28/Q28,"") -> 0.26904949 | T28: =IFERROR(__xludf.DUMMYFUNCTION("""COMPUTED_VALUE"""),"Altria Group") -> Altria Group | U28: =IFERROR(__xludf.DUMMYFUNCTION("""COMPUTED_VALUE"""),0.5641871201771329) -> 0.56418712
A29: Cost Structure | B29: 2020 | C29: 2021 | D29: Amazon | E29: =SUMIF(Cleaned_Data!C$2:C$2013,D29,Cleaned_Data!N$2:N$2013) -> 443298000000 | J29: =IFERROR(__xludf.DUMMYFUNCTION("""COMPUTED_VALUE"""),"APA Corporation") -> APA Corporation | K29: =IFERROR(__xludf.DUMMYFUNCTION("""COMPUTED_VALUE"""),-2.676E9) -> -2676000000 | L29: =IFERROR(__xludf.DUMMYFUNCTION("""COMPUTED_VALUE"""),6.027E9) -> 6027000000 | O29: Accenture | P29: =SUMIF(Cleaned_Data!C$2:C$2013,O29,Cleaned_Data!K$2:K$2013) -> 7621529000 | Q29: =SUMIF(Cleaned_Data!C$2:C$2013,O29,Cleaned_Data!N$2:N$2013) -> 50533389000 | R29: =IFERROR(P29/Q29,"") -> 0.15082165 | T29: =IFERROR(__xludf.DUMMYFUNCTION("""COMPUTED_VALUE"""),"Moderna") -> Moderna | U29: =IFERROR(__xludf.DUMMYFUNCTION("""COMPUTED_VALUE"""),0.543879293213128) -> 0.54387929
A30: Cost of Revenue | B30: =SUMPRODUCT((YEAR(Cleaned_Data!$B$2:$B$2013)=B$29)*Cleaned_Data!$P$2:$P$2013) -> 3467317941000 | C30: =SUMPRODUCT((YEAR(Cleaned_Data!$B$2:$B$2013)=C$29)*Cleaned_Data!$P$2:$P$2013) -> 4537383866000 | D30: Amcor | E30: =SUMIF(Cleaned_Data!C$2:C$2013,D30,Cleaned_Data!N$2:N$2013) -> 12861000000 | J30: =IFERROR(__xludf.DUMMYFUNCTION("""COMPUTED_VALUE"""),"AT&T") -> AT&T | K30: =IFERROR(__xludf.DUMMYFUNCTION("""COMPUTED_VALUE"""),3.07E10) -> 30700000000 | L30: =IFERROR(__xludf.DUMMYFUNCTION("""COMPUTED_VALUE"""),1.76015E11) -> 176015000000 | O30: Activision Blizzard | P30: =SUMIF(Cleaned_Data!C$2:C$2013,O30,Cleaned_Data!K$2:K$2013) -> 3274000000 | Q30: =SUMIF(Cleaned_Data!C$2:C$2013,O30,Cleaned_Data!N$2:N$2013) -> 9053000000 | R30: =IFERROR(P30/Q30,"") -> 0.36164807 | T30: =IFERROR(__xludf.DUMMYFUNCTION("""COMPUTED_VALUE"""),"S&P Global") -> S&P Global | U30: =IFERROR(__xludf.DUMMYFUNCTION("""COMPUTED_VALUE"""),0.5418524021792966) -> 0.5418524
A31: Operating Expenses | B31: =SUMPRODUCT((YEAR(Cleaned_Data!$B$2:$B$2013)=B$29)*Cleaned_Data!$O$2:$O$2013) -> 4821060545000 | C31: =SUMPRODUCT((YEAR(Cleaned_Data!$B$2:$B$2013)=C$29)*Cleaned_Data!$O$2:$O$2013) -> 6298459761000 | D31: Ameren Corp | E31: =SUMIF(Cleaned_Data!C$2:C$2013,D31,Cleaned_Data!N$2:N$2013) -> 5735000000 | J31: =IFERROR(__xludf.DUMMYFUNCTION("""COMPUTED_VALUE"""),"AbbVie") -> AbbVie | K31: =IFERROR(__xludf.DUMMYFUNCTION("""COMPUTED_VALUE"""),1.9467E10) -> 19467000000 | L31: =IFERROR(__xludf.DUMMYFUNCTION("""COMPUTED_VALUE"""),5.5169E10) -> 55169000000 | O31: ADM | P31: =SUMIF(Cleaned_Data!C$2:C$2013,O31,Cleaned_Data!K$2:K$2013) -> 2707000000 | Q31: =SUMIF(Cleaned_Data!C$2:C$2013,O31,Cleaned_Data!N$2:N$2013) -> 80137000000 | R31: =IFERROR(P31/Q31,"") -> 0.033779652 | T31: =IFERROR(__xludf.DUMMYFUNCTION("""COMPUTED_VALUE"""),"Regeneron Pharmaceuticals") -> Regeneron Pharmaceuticals | U31: =IFERROR(__xludf.DUMMYFUNCTION("""COMPUTED_VALUE"""),0.538506461418667) -> 0.53850646
A32: SG&A | B32: =SUMPRODUCT((YEAR(Cleaned_Data!$B$2:$B$2013)=B$29)*Cleaned_Data!$H$2:$H$2013) -> 911532452000 | C32: =SUMPRODUCT((YEAR(Cleaned_Data!$B$2:$B$2013)=C$29)*Cleaned_Data!$H$2:$H$2013) -> 1243437938000 | D32: American Airlines Group | E32: =SUMIF(Cleaned_Data!C$2:C$2013,D32,Cleaned_Data!N$2:N$2013) -> 18687000000 | J32: =IFERROR(__xludf.DUMMYFUNCTION("""COMPUTED_VALUE"""),"Abbott Laboratories") -> Abbott Laboratories | K32: =IFERROR(__xludf.DUMMYFUNCTION("""COMPUTED_VALUE"""),9.292E9) -> 9292000000 | L32: =IFERROR(__xludf.DUMMYFUNCTION("""COMPUTED_VALUE"""),4.2308E10) -> 42308000000 | O32: Adobe | P32: =SUMIF(Cleaned_Data!C$2:C$2013,O32,Cleaned_Data!K$2:K$2013) -> 5516000000 | Q32: =SUMIF(Cleaned_Data!C$2:C$2013,O32,Cleaned_Data!N$2:N$2013) -> 15099000000 | R32: =IFERROR(P32/Q32,"") -> 0.36532221 | T32: =IFERROR(__xludf.DUMMYFUNCTION("""COMPUTED_VALUE"""),"CME Group") -> CME Group | U32: =IFERROR(__xludf.DUMMYFUNCTION("""COMPUTED_VALUE"""),0.5381939915655841) -> 0.53819399
A33: R&D | B33: =SUMPRODUCT((YEAR(Cleaned_Data!$B$2:$B$2013)=B$29)*Cleaned_Data!$E$2:$E$2013) -> 180628916000 | C33: =SUMPRODUCT((YEAR(Cleaned_Data!$B$2:$B$2013)=C$29)*Cleaned_Data!$E$2:$E$2013) -> 221617415000 | D33: American Electric Power | E33: =SUMIF(Cleaned_Data!C$2:C$2013,D33,Cleaned_Data!N$2:N$2013) -> 15784600000 | J33: =IFERROR(__xludf.DUMMYFUNCTION("""COMPUTED_VALUE"""),"Abiomed") -> Abiomed | K33: =IFERROR(__xludf.DUMMYFUNCTION("""COMPUTED_VALUE"""),2.61956E8) -> 261956000 | L33: =IFERROR(__xludf.DUMMYFUNCTION("""COMPUTED_VALUE"""),9.73635E8) -> 973635000 | O33: Advance Auto Parts | P33: =SUMIF(Cleaned_Data!C$2:C$2013,O33,Cleaned_Data!K$2:K$2013) -> 1087428000 | Q33: =SUMIF(Cleaned_Data!C$2:C$2013,O33,Cleaned_Data!N$2:N$2013) -> 11619092500 | R33: =IFERROR(P33/Q33,"") -> 0.093589753 | T33: =IFERROR(__xludf.DUMMYFUNCTION("""COMPUTED_VALUE"""),"MSCI") -> MSCI | U33: =IFERROR(__xludf.DUMMYFUNCTION("""COMPUTED_VALUE"""),0.5354430029957786) -> 0.535443
D34: American Express | E34: =SUMIF(Cleaned_Data!C$2:C$2013,D34,Cleaned_Data!N$2:N$2013) -> 38136000000 | J34: =IFERROR(__xludf.DUMMYFUNCTION("""COMPUTED_VALUE"""),"Accenture") -> Accenture | K34: =IFERROR(__xludf.DUMMYFUNCTION("""COMPUTED_VALUE"""),7.621529E9) -> 7621529000 | L34: =IFERROR(__xludf.DUMMYFUNCTION("""COMPUTED_VALUE"""),5.0533389E10) -> 50533389000 | O34: Advanced Micro Devices | P34: =SUMIF(Cleaned_Data!C$2:C$2013,O34,Cleaned_Data!K$2:K$2013) -> 3044000000 | Q34: =SUMIF(Cleaned_Data!C$2:C$2013,O34,Cleaned_Data!N$2:N$2013) -> 14852000000 | R34: =IFERROR(P34/Q34,"") -> 0.20495556
D35: American International Group | E35: =SUMIF(Cleaned_Data!C$2:C$2013,D35,Cleaned_Data!N$2:N$2013) -> 44339000000 | J35: =IFERROR(__xludf.DUMMYFUNCTION("""COMPUTED_VALUE"""),"Activision Blizzard") -> Activision Blizzard | K35: =IFERROR(__xludf.DUMMYFUNCTION("""COMPUTED_VALUE"""),3.274E9) -> 3274000000 | L35: =IFERROR(__xludf.DUMMYFUNCTION("""COMPUTED_VALUE"""),9.053E9) -> 9053000000 | O35: AES Corp | P35: =SUMIF(Cleaned_Data!C$2:C$2013,O35,Cleaned_Data!K$2:K$2013) -> 2699000000 | Q35: =SUMIF(Cleaned_Data!C$2:C$2013,O35,Cleaned_Data!N$2:N$2013) -> 10931000000 | R35: =IFERROR(P35/Q35,"") -> 0.24691245
D36: American Tower | E36: =SUMIF(Cleaned_Data!C$2:C$2013,D36,Cleaned_Data!N$2:N$2013) -> 8592800000 | J36: =IFERROR(__xludf.DUMMYFUNCTION("""COMPUTED_VALUE"""),"Adobe") -> Adobe | K36: =IFERROR(__xludf.DUMMYFUNCTION("""COMPUTED_VALUE"""),5.516E9) -> 5516000000 | L36: =IFERROR(__xludf.DUMMYFUNCTION("""COMPUTED_VALUE"""),1.5099E10) -> 15099000000 | O36: Aflac | P36: =SUMIF(Cleaned_Data!C$2:C$2013,O36,Cleaned_Data!K$2:K$2013) -> 5548000000 | Q36: =SUMIF(Cleaned_Data!C$2:C$2013,O36,Cleaned_Data!N$2:N$2013) -> 22583000000 | R36: =IFERROR(P36/Q36,"") -> 0.24567152
B37: =B30/B17 -> 0.61883777 | C37: =C30/C17 -> 0.5993591 | D37: American Water Works | E37: =SUMIF(Cleaned_Data!C$2:C$2013,D37,Cleaned_Data!N$2:N$2013) -> 3889000000 | J37: =IFERROR(__xludf.DUMMYFUNCTION("""COMPUTED_VALUE"""),"Advance Auto Parts") -> Advance Auto Parts | K37: =IFERROR(__xludf.DUMMYFUNCTION("""COMPUTED_VALUE"""),1.087428E9) -> 1087428000 | L37: =IFERROR(__xludf.DUMMYFUNCTION("""COMPUTED_VALUE"""),1.16190925E10) -> 11619092500 | O37: Agilent Technologies | P37: =SUMIF(Cleaned_Data!C$2:C$2013,O37,Cleaned_Data!K$2:K$2013) -> 1318000000 | Q37: =SUMIF(Cleaned_Data!C$2:C$2013,O37,Cleaned_Data!N$2:N$2013) -> 6142000000 | R37: =IFERROR(P37/Q37,"") -> 0.21458808
B38: =B31/B17 -> 0.86045019 | C38: =C31/C17 -> 0.83198585 | D38: Ameriprise Financial | E38: =SUMIF(Cleaned_Data!C$2:C$2013,D38,Cleaned_Data!N$2:N$2013) -> 12977000000 | J38: =IFERROR(__xludf.DUMMYFUNCTION("""COMPUTED_VALUE"""),"Advanced Micro Devices") -> Advanced Micro Devices | K38: =IFERROR(__xludf.DUMMYFUNCTION("""COMPUTED_VALUE"""),3.044E9) -> 3044000000 | L38: =IFERROR(__xludf.DUMMYFUNCTION("""COMPUTED_VALUE"""),1.4852E10) -> 14852000000 | O38: Air Products & Chemicals | P38: =SUMIF(Cleaned_Data!C$2:C$2013,O38,Cleaned_Data!K$2:K$2013) -> 2333400000 | Q38: =SUMIF(Cleaned_Data!C$2:C$2013,O38,Cleaned_Data!N$2:N$2013) -> 10323000000 | R38: =IFERROR(P38/Q38,"") -> 0.22603894
B39: =B32/B17 -> 0.16268791 | C39: =C32/C17 -> 0.16425012 | D39: AmerisourceBergen | E39: =SUMIF(Cleaned_Data!C$2:C$2013,D39,Cleaned_Data!N$2:N$2013) -> 204321190000 | J39: =IFERROR(__xludf.DUMMYFUNCTION("""COMPUTED_VALUE"""),"Aflac") -> Aflac | K39: =IFERROR(__xludf.DUMMYFUNCTION("""COMPUTED_VALUE"""),5.548E9) -> 5548000000 | L39: =IFERROR(__xludf.DUMMYFUNCTION("""COMPUTED_VALUE"""),2.2583E10) -> 22583000000 | O39: Akamai Technologies | P39: =SUMIF(Cleaned_Data!C$2:C$2013,O39,Cleaned_Data!K$2:K$2013) -> 759729000 | Q39: =SUMIF(Cleaned_Data!C$2:C$2013,O39,Cleaned_Data!N$2:N$2013) -> 3402152000 | R39: =IFERROR(P39/Q39,"") -> 0.22330836
B40: =B33/B17 -> 0.032238173 | C40: =C33/C17 -> 0.029274229 | D40: Ametek | E40: =SUMIF(Cleaned_Data!C$2:C$2013,D40,Cleaned_Data!N$2:N$2013) -> 4927977000 | J40: =IFERROR(__xludf.DUMMYFUNCTION("""COMPUTED_VALUE"""),"Agilent Technologies") -> Agilent Technologies | K40: =IFERROR(__xludf.DUMMYFUNCTION("""COMPUTED_VALUE"""),1.318E9) -> 1318000000 | L40: =IFERROR(__xludf.DUMMYFUNCTION("""COMPUTED_VALUE"""),6.142E9) -> 6142000000 | O40: Alaska Air Group | P40: =SUMIF(Cleaned_Data!C$2:C$2013,O40,Cleaned_Data!K$2:K$2013) -> 561132000 | Q40: =SUMIF(Cleaned_Data!C$2:C$2013,O40,Cleaned_Data!N$2:N$2013) -> 3312900000 | R40: =IFERROR(P40/Q40,"") -> 0.16937789
...

Sheet Pivot Table 1

Sheet Dashboard
